<?xml version="1.0"?>

  <!-- UNIMATE Puma 560 Manipulator -->
  <robot name="puma560" xmlns:xacro="http://www.ros.org/wiki/xacro">
  
  <!-- Constants for robot dimensions -->
  <xacro:property name="Pi" value="3.1415926535897931"/>

  <!-- DH parameters for frame modeling -->
  <!-- DH parameter for base to link 1 -->
  <xacro:property name="alpha1" value="${Pi/2}"/>
  <xacro:property name="d1" value="${0.54864 + 0.07493}"/>
  <xacro:property name="a1" value="0"/>

  <!-- DH parameter for link 1 to link 2 -->
  <xacro:property name="alpha2" value="0"/>
  <xacro:property name="d2" value="${0.14224 + 0.0254}"/>
  <xacro:property name="a2" value="${0.432}"/>

  <!-- DH parameter for link 2 to link 3 -->
  <xacro:property name="alpha3" value="-${Pi/2}"/>
  <xacro:property name="d3" value="${0.0381}"/>
  <xacro:property name="a3" value="${0.35179+0.02032}"/>

    <!-- DH parameter for link 2 to link 3 -->
  <xacro:property name="alpha3" value="-${Pi/2}"/>
  <xacro:property name="d4" value="${0.05998}"/>

  <!-- Import Rviz colors -->
  <xacro:include filename="$(find puma560_description)/urdf/materials.xacro" />

  <!-- Link definitions -->
  <link name="world"/>

  <link name="puma_base">
    <visual>
     <origin xyz="0 0 -${d1}" rpy="${Pi/2} 0 0" />
     <geometry>
      <mesh filename="package://puma560_description/meshes/puma_base.stl" />
     </geometry>
     <material name="grey"/>
  </visual>
</link>

<link name="puma_link_1">
  <visual>
 <origin xyz="0 0 0" rpy="-${Pi/2} 0 -${Pi/2}" />
 <geometry>
    <mesh filename="package://puma560_description/meshes/puma_link_1.stl" />
   </geometry>
   <material name="metal"/>
 </visual>
</link>

 <link name="puma_link_2">
  <visual>
   <origin xyz="0 0 0" rpy="${Pi} -${Pi/2} 0" />
   <geometry>
    <mesh filename="package://puma560_description/meshes/puma_link_2.stl" />
   </geometry>
   <material name="metal"/>
 </visual>
</link>

<link name="puma_link_3">
  <visual>
   <origin xyz="0 0 0" rpy="${Pi/2} -${Pi/2} 0 " />
   <geometry>
    <mesh filename="package://puma560_description/meshes/puma_link_3.stl" />
   </geometry>
   <material name="metal"/>
 </visual>
</link>

<link name="puma_link_4">
  <visual>
   <origin xyz="0 0 0" rpy="-${Pi/2} 0 0 " />
   <geometry>
    <mesh filename="package://puma560_description/meshes/puma_link_4.stl" />
   </geometry>
   <material name="grey"/>
 </visual>
</link>

<link name="puma_link_5">
  <visual>
   <origin xyz="0 0 0" rpy="0 ${Pi/2} 0 " />
   <geometry>
    <mesh filename="package://puma560_description/meshes/puma_link_5.stl" />
   </geometry>
   <material name="grey"/>
 </visual>
</link>

<!-- Joint definitions -->

<joint name="world" type="fixed">
  <parent link="world"/>
  <child link="puma_base"/>
  <origin xyz="0 0 ${d1}" rpy="0 0 0" />
  <axis xyz="0 0 1" />
</joint>

<joint name="base_to_link_1" type="continuous">
  <parent link="puma_base"/>
  <child link="puma_link_1"/>
  <origin xyz="0 0 0" rpy="0 0 0" />
  <axis xyz="0 0 1" />
</joint>

<joint name="link_1_to_link_2" type="continuous">
  <parent link="puma_link_1"/>
  <child link="puma_link_2"/>
  <origin xyz="0 ${d2} 0" rpy="${alpha1} 0 0" />
  <axis xyz="0 0 1" />
</joint>

<joint name="link_2_to_link_3" type="continuous">
  <parent link="puma_link_2"/>
  <child link="puma_link_3"/>
  <origin xyz="${a2} 0 0" rpy="0 0 0" />
  <axis xyz="0 0 1" />
</joint>

<joint name="link_3_to_link_4" type="continuous">
  <parent link="puma_link_3"/>
  <child link="puma_link_4"/>
  <origin xyz="${a3} 0 ${d3}" rpy="0 ${Pi/2} 0" />
  <axis xyz="0 0 1" />
</joint>

<joint name="link_4_to_link_5" type="continuous">
  <parent link="puma_link_4"/>
  <child link="puma_link_5"/>
  <origin xyz="0 0 ${d4}" rpy="${Pi/2} 0 0" />
  <axis xyz="0 0 1" />
</joint>


</robot>
