<?xml version="1.0" ?>
<!-- =================================================================================== -->
<!-- |    This document was autogenerated by xacro from /home/jwcjdenissen/jade_workspace/src/puma560/puma560_description/urdf/puma560_v4.xacro | -->
<!-- |    EDITING THIS FILE BY HAND IS NOT RECOMMENDED                                 | -->
<!-- =================================================================================== -->
<!-- UNIMATE Puma 560 Manipulator -->
<robot name="puma560" xmlns:xacro="http://www.ros.org/wiki/xacro">
  <material name="black">
    <color rgba="0.0 0.0 0.0 1.0"/>
  </material>
  <material name="blue">
    <color rgba="0.0 0.0 0.8 1.0"/>
  </material>
  <material name="green">
    <color rgba="0.0 0.8 0.0 1.0"/>
  </material>
  <material name="grey">
    <color rgba="0.2 0.2 0.2 1.0"/>
  </material>
  <material name="red">
    <color rgba="0.8 0.0 0.0 1.0"/>
  </material>
  <material name="red_transparent">
    <color rgba="0.8 0.0 0.0 0.5"/>
  </material>
  <material name="white">
    <color rgba="1.0 1.0 1.0 1.0"/>
  </material>
  <material name="orange">
    <color rgba="1.0 0.423529411765 0.0392156862745 1.0"/>
  </material>
  <material name="brown">
    <color rgba="0.870588235294 0.811764705882 0.764705882353 1.0"/>
  </material>
  <material name="metal">
    <color rgba="0.827450980392 0.827450980392 0.827450980392 1"/>
  </material>
  <material name="wood">
    <color rgba="0.803921568627 0.521568627451 0.247058823529 1"/>
  </material>
  <!-- Base link-->
  <gazebo reference="puma_base">
    <material>Gazebo/Grey</material>
  </gazebo>
  <!-- Link 1 -->
  <gazebo reference="puma_link_1">
    <material>Gazebo/Metal</material>
  </gazebo>
  <!-- Link 2 -->
  <gazebo reference="puma_link_2">
    <material>Gazebo/Metal</material>
  </gazebo>
  <!-- Link 3 -->
  <gazebo reference="puma_link_3">
    <material>Gazebo/Metal</material>
  </gazebo>
  <!-- Link 4 -->
  <gazebo reference="puma_link_4">
    <material>Gazebo/Orange</material>
  </gazebo>
  <!-- Link 5 -->
  <gazebo reference="puma_link_5">
    <material>Gazebo/Orange</material>
  </gazebo>
  <!-- Link definitions -->
  <link name="world"/>
  <joint name="world" type="fixed">
    <parent link="world"/>
    <child link="puma_base"/>
    <origin rpy="0 0 0" xyz="0 0 0.54864"/>
    <axis xyz="0 0 1"/>
  </joint>
  <link name="puma_base">
    <visual>
      <origin rpy="0 0 0" xyz="0 0 0"/>
      <geometry>
        <mesh filename="package://puma560_description/meshes/puma_base.stl"/>
      </geometry>
      <material name="grey"/>
    </visual>
    <collision>
      <origin rpy="0 0 0" xyz="0 0 0"/>
      <geometry>
        <mesh filename="package://puma560_description/meshes/puma_base_collision.stl"/>
      </geometry>
    </collision>
    <!-- Inertia parameters 
      mass and center of mass (com)
      inertia_diagonal defined as [Ixx Iyy Izz]
      inertia_off_diagonal defined as [Ixy Ixz Iyz]
    -->
    <inertial>
      <origin rpy="0 0 0" xyz="-0.0 0.02196 -0.356146"/>
      <mass value="42.62416"/>
      <inertia ixx="1.48565" ixy="0" ixz="0" iyy="1.36144" iyz="0.05984" izz="0.43392"/>
    </inertial>
    <inertial>
      <origin rpy="0 0 0" xyz="-0.0 0.02196 -0.356146"/>
      <mass value="15.78673"/>
      <inertia ixx="0.55024" ixy="0" ixz="0" iyy="0.50424" iyz="0.02216" izz="0.16071"/>
    </inertial>
  </link>
  <joint name="link_1" type="continuous">
    <parent link="puma_base"/>
    <child link="puma_link_1"/>
    <origin rpy="0 0 0" xyz="0 0 0.07493"/>
    <axis xyz="0 0 1"/>
  </joint>
  <link name="puma_link_1">
    <visual>
      <origin rpy="0 0 0" xyz="0 0 0"/>
      <geometry>
        <mesh filename="package://puma560_description/meshes/puma_link_1.stl"/>
      </geometry>
      <material name="metal"/>
    </visual>
    <collision>
      <origin rpy="0 0 0" xyz="0 0 0"/>
      <geometry>
        <mesh filename="package://puma560_description/meshes/puma_link_1_collision.stl"/>
      </geometry>
    </collision>
    <!-- Inertia parameters 
      mass and center of mass (com)
      inertia_diagonal defined as [Ixx Iyy Izz]
      inertia_off_diagonal defined as [Ixy Ixz Iyz]
    -->
    <inertial>
      <origin rpy="0 0 0" xyz="-0.0 0.022503 -0.002794"/>
      <mass value="11.97216"/>
      <inertia ixx="0.07379" ixy="0" ixz="0" iyy="0.03595" iyz="-0.00075" izz="0.07334"/>
    </inertial>
    <inertial>
      <origin rpy="0 0 0" xyz="-0.0 0.022503 -0.002794"/>
      <mass value="4.43413"/>
      <inertia ixx="0.02733" ixy="0" ixz="0" iyy="0.01332" iyz="-0.00028" izz="0.02716"/>
    </inertial>
  </link>
  <joint name="link_2" type="continuous">
    <parent link="puma_link_1"/>
    <child link="puma_link_2"/>
    <origin rpy="1.57079632679 0 0" xyz="0 0.16764 0"/>
    <axis xyz="0 0 1"/>
  </joint>
  <link name="puma_link_2">
    <visual>
      <origin rpy="0 0 0" xyz="0 0 0"/>
      <geometry>
        <mesh filename="package://puma560_description/meshes/puma_link_2.stl"/>
      </geometry>
      <material name="metal"/>
    </visual>
    <collision>
      <origin rpy="0 0 0" xyz="0 0 0"/>
      <geometry>
        <mesh filename="package://puma560_description/meshes/puma_link_2_collision.stl"/>
      </geometry>
    </collision>
    <!-- Inertia parameters 
      mass and center of mass (com)
      inertia_diagonal defined as [Ixx Iyy Izz]
      inertia_off_diagonal defined as [Ixy Ixz Iyz]
    -->
    <inertial>
      <origin rpy="0 0 0" xyz="0.082741 4.7e-05 -0.047642"/>
      <mass value="45.48585"/>
      <inertia ixx="0.26252" ixy="2e-05" ixz="0.26252" iyy="1.61075" iyz="-0.00013" izz="1.78135"/>
    </inertial>
    <inertial>
      <origin rpy="0 0 0" xyz="0.082741 4.7e-05 -0.047642"/>
      <mass value="16.84661"/>
      <inertia ixx="0.09723" ixy="1e-05" ixz="0.00435" iyy="0.59657" iyz="-5e-05" izz="0.65976"/>
    </inertial>
  </link>
  <joint name="link_3" type="continuous">
    <parent link="puma_link_2"/>
    <child link="puma_link_3"/>
    <origin rpy="0 0 0" xyz="0.4318 0 0"/>
    <axis xyz="0 0 1"/>
  </joint>
  <link name="puma_link_3">
    <visual>
      <origin rpy="0 0 0" xyz="0 0 0"/>
      <geometry>
        <mesh filename="package://puma560_description/meshes/puma_link_3.stl"/>
      </geometry>
      <material name="metal"/>
    </visual>
    <collision>
      <origin rpy="0 0 0" xyz="0 0 0"/>
      <geometry>
        <mesh filename="package://puma560_description/meshes/puma_link_3_collision.stl"/>
      </geometry>
    </collision>
    <!-- Inertia parameters 
      mass and center of mass (com)
      inertia_diagonal defined as [Ixx Iyy Izz]
      inertia_off_diagonal defined as [Ixy Ixz Iyz]
    -->
    <inertial>
      <origin rpy="0 0 0" xyz="0.088782 -1e-06 0.038098"/>
      <mass value="12.42678"/>
      <inertia ixx="0.02482" ixy="0" ixz="0" iyy="0.22306" iyz="0" izz="0.23586"/>
    </inertial>
    <inertial>
      <origin rpy="0 0 0" xyz="0.088782 -1e-06 0.038098"/>
      <mass value="4.60251"/>
      <inertia ixx="0.00919" ixy="0" ixz="1e-05" iyy="0.08262" iyz="0" izz="0.08735"/>
    </inertial>
  </link>
  <joint name="link_4" type="continuous">
    <parent link="puma_link_3"/>
    <child link="puma_link_4"/>
    <origin rpy="0 1.57079632679 0" xyz="0.35179 0 0.0381 "/>
    <axis xyz="0 0 1"/>
  </joint>
  <link name="puma_link_4">
    <visual>
      <origin rpy="0 0 0" xyz="0 0 0"/>
      <geometry>
        <mesh filename="package://puma560_description/meshes/puma_link_4.stl"/>
      </geometry>
      <material name="orange"/>
    </visual>
    <collision>
      <origin rpy="0 0 0" xyz="0 0 0"/>
      <geometry>
        <mesh filename="package://puma560_description/meshes/puma_link_4_collision.stl"/>
      </geometry>
    </collision>
    <!-- Inertia parameters 
      mass and center of mass (com)
      inertia_diagonal defined as [Ixx Iyy Izz]
      inertia_off_diagonal defined as [Ixy Ixz Iyz]
    -->
    <inertial>
      <origin rpy="0 0 0" xyz="-0.0 -0.0 0.047887"/>
      <mass value="1.27113"/>
      <inertia ixx="0.00209" ixy="0" ixz="0" iyy="0.00199" iyz="0" izz="0.00126"/>
    </inertial>
    <inertial>
      <origin rpy="0 0 0" xyz="-0.0 -0.0 0.047887"/>
      <mass value="0.47079"/>
      <inertia ixx="0.00077" ixy="0" ixz="0" iyy="0.00074" iyz="0" izz="0.00047"/>
    </inertial>
  </link>
  <joint name="link_5" type="continuous">
    <parent link="puma_link_4"/>
    <child link="puma_link_5"/>
    <origin rpy="0 -1.57079632679 -1.57079632679" xyz="0 0 0.0803 "/>
    <axis xyz="0 0 1"/>
  </joint>
  <link name="puma_link_5">
    <visual>
      <origin rpy="0 0 0" xyz="0 0 0"/>
      <geometry>
        <mesh filename="package://puma560_description/meshes/puma_link_5.stl"/>
      </geometry>
      <material name="orange"/>
    </visual>
    <collision>
      <origin rpy="0 0 0" xyz="0 0 0"/>
      <geometry>
        <mesh filename="package://puma560_description/meshes/puma_link_5_collision.stl"/>
      </geometry>
    </collision>
    <!-- Inertia parameters 
      mass and center of mass (com)
      inertia_diagonal defined as [Ixx Iyy Izz]
      inertia_off_diagonal defined as [Ixy Ixz Iyz]
    -->
    <inertial>
      <origin rpy="0 0 0" xyz="0.010974 0.0 0.0"/>
      <mass value="0.209"/>
      <inertia ixx="5e-05" ixy="0" ixz="0" iyy="0.00012" iyz="0" izz="0.00012"/>
    </inertial>
    <inertial>
      <origin rpy="0 0 0" xyz="0.010974 0.0 0.0"/>
      <mass value="0.07741"/>
      <inertia ixx="2e-05" ixy="0" ixz="0" iyy="4e-05" iyz="0" izz="5e-05"/>
    </inertial>
  </link>  
  
  <transmission name="tranmission_1">
    <type>transmission_interface/SimpleTransmission</type>
    <joint name="link_1">
      <hardwareInterface>EffortJointInterface</hardwareInterface>
    </joint>
    <actuator name="actuator_1">
      <hardwareInterface>EffortJointInterface</hardwareInterface>
      <mechanicalReduction>1</mechanicalReduction>
    </actuator>
  </transmission>
</robot>
<!--     Parameters for uniform body 
    <xacro:general_inertia_definition
      mass="0" 
      com="${[0, 0, 0, 0, 0, 0]}"
      inertia_diagonal="${[0, 0, 0]}"
      inertia_off_diagonal="${[0, 0, 0]}"
      />
    -->

