<?xml version="1.0"?>

  <!-- UNIMATE Puma 560 Manipulator -->
  <robot name="puma560" xmlns:xacro="http://www.ros.org/wiki/xacro">
  
  <!-- Constants for robot dimensions -->
  <xacro:property name="Pi" value="3.1415926535897931"/>

  <!-- DH parameters for frame modeling -->
  <!-- DH parameter for base to link 1 -->
  <xacro:property name="alpha1" value="${Pi/2}"/>
  <xacro:property name="d1" value="${0.54864 + 0.07493}"/>
  <xacro:property name="a1" value="0"/>

  <!-- DH parameter for link 1 to link 2 -->
  <xacro:property name="alpha2" value="0"/>
  <xacro:property name="d2" value="-${0.14224 + 0.0254}"/>
  <xacro:property name="a2" value="${0.432}"/>

  <!-- DH parameter for link 2 to link 3 -->
  <xacro:property name="alpha3" value="-${Pi/2}"/>
  <xacro:property name="d3" value="${0.0381}"/>
  <xacro:property name="a3" value="${0.35179}"/>

  <!-- Import Rviz colors -->
  <xacro:include filename="$(find puma560_description)/urdf/materials.xacro" />

  <!-- Link definitions -->
  <link name="world"/>

  <link name="puma_base">
    <visual>
     <origin xyz="0 0 0" rpy="0 0 0" />
     <geometry>
      <cylinder length="0.5" radius="0.1"/>
     </geometry>
     <material name="grey"/>
  </visual>
</link>

<link name="puma_link_1">
  <visual>
   <origin xyz="0 0 0" rpy="0 0 0" />
   <geometry>
    <cylinder length="0.5" radius="0.1"/>
   </geometry>
   <material name="metal"/>
 </visual>
</link>

<link name="puma_link_2">
  <visual>
   <origin xyz="0 0 0" rpy="0 0 0" />
   <geometry>
    <cylinder length="0.5" radius="0.1"/>
   </geometry>
   <material name="metal"/>
 </visual>
</link>

<link name="puma_link_3">
  <visual>
   <origin xyz="0 0 0" rpy="0 0 0" />
   <geometry>
    <cylinder length="0.5" radius="0.1"/>
   </geometry>
   <material name="metal"/>
 </visual>
</link>

<!-- Joint definitions -->

<joint name="world" type="continuous">
  <parent link="world"/>
  <child link="puma_base"/>
  <origin xyz="0 0 0" rpy="0 0 0" />
  <axis xyz="0 0 1" />
</joint>

<joint name="base_to_link_1" type="continuous">
  <parent link="puma_base"/>
  <child link="puma_link_1"/>
  <origin xyz="0 0 ${d1}" rpy="${alpha1} 0 0" />
  <axis xyz="0 0 1" />
</joint>

<joint name="link_1_to_link_2" type="continuous">
  <parent link="puma_link_1"/>
  <child link="puma_link_2"/>
  <origin xyz="${a2} 0 ${d2}" rpy="${alpha2} 0 0" />
  <axis xyz="0 0 1" />
</joint>

<joint name="link_2_to_link_3" type="fixed">
  <parent link="puma_link_2"/>
  <child link="puma_link_3"/>
  <origin xyz="${a3} 0 ${d3}" rpy="${alpha3} 0 0" />
  <axis xyz="0 0 1" />
</joint>


</robot>
