<?xml version="1.0"?>

<!-- UNIMATE Puma 560 Manipulator -->
<robot name="puma560" xmlns:xacro="http://www.ros.org/wiki/xacro">

  <!-- Constants for robot dimensions -->
  <xacro:property name="Pi" value="${3.1415926535897931}"/>

  <!-- Geometric parameters for base -->
  <xacro:property name="offset_z_base" value="${0.54864}"/>
  <xacro:property name="offset_z_link_1" value="${0.07493}"/>
  <xacro:property name="offset_y_link_2" value="${0.14224 + 0.0254}"/>

  <!-- Inertia parameters 
  mass and center of mass (com)
  inertia_diagonal defined as [Ixx Iyy Izz]
  inertia_off_diagonal defined as [Ixy Ixz Iyz]
-->
<xacro:macro name="general_inertia_definition" params="mass com inertia_diagonal inertia_off_diagonal">
  <inertial>
    <origin xyz="${com[0]} ${com[1]} ${com[2]}" rpy="${com[3]} ${com[4]} ${com[5]}"/>
    <mass value="${mass}"/>
    <inertia 
      ixx="${inertia_diagonal[0]}"  ixy="${inertia_off_diagonal[0]}" ixz="${inertia_off_diagonal[1]}" 
      iyy="${inertia_diagonal[1]}"  iyz="${inertia_off_diagonal[2]}"
      izz="${inertia_diagonal[2]}"
      />
    </inertial>
  </xacro:macro>

  <!-- Import Rviz colors -->
  <xacro:include filename="$(find puma560_description)/urdf/materials.xacro" />

  <!-- Import all Gazebo-customization elements, including Gazebo colors -->
  <xacro:include filename="$(find puma560_description)/urdf/puma560.gazebo" />

  <!-- Link definitions -->
  <link name="world"/>

  <joint name="world" type="fixed">
    <parent link="world"/>
    <child link="puma_base"/>
    <origin xyz="0 0 ${offset_z_base}" rpy="0 0 0" />
    <axis xyz="0 0 1" />
  </joint>

  <link name="puma_base">

    <visual>
      <origin xyz="0 0 0" rpy="0 0 0" />
      <geometry>
        <mesh filename="package://puma560_description/meshes/puma_base.stl" />
      </geometry>
      <material name="grey"/>
    </visual>

    <collision>
      <origin xyz="0 0 0" rpy="0 0 0" />
      <geometry>
        <mesh filename="package://puma560_description/meshes/puma_base_collision.stl" />
      </geometry>
    </collision>

      <!-- Inertia parameters 
      mass and center of mass (com)
      inertia_diagonal defined as [Ixx Iyy Izz]
      inertia_off_diagonal defined as [Ixy Ixz Iyz]

    <xacro:general_inertia_definition
      mass="15.78673" 
      com="${[-0.000000, 0.021960, -0.356146, 0, 0, 0]}"
      inertia_diagonal="${[0.55024, 0.50424, 0.16071]}"
      inertia_off_diagonal="${[0, 0, 0.02216]}"
      />

      <!-- Inertia parameters 
      mass and center of mass (com)
      inertia_diagonal defined as [Ixx Iyy Izz]
      inertia_off_diagonal defined as [Ixy Ixz Iyz]
    -->
    <xacro:general_inertia_definition
      mass="42.62416" 
      com="${[-0.000000, 0.021960, -0.356146, 0, 0, 0]}"
      inertia_diagonal="${[1.48565, 1.36144, 0.43392]}"
      inertia_off_diagonal="${[0, 0, 0.05984]}"
      />

    </link>

    <joint name="link_1" type="continuous">
      <parent link="puma_base"/>
      <child link="puma_link_1"/>
      <origin xyz="0 0 ${offset_z_link_1}" rpy="0 0 0" />
      <axis xyz="0 0 1" />
    </joint>

    <link name="puma_link_1">

      <visual>
        <origin xyz="0 0 0" rpy="0 0 0" />
        <geometry>
          <mesh filename="package://puma560_description/meshes/puma_link_1.stl" />
        </geometry>
        <material name="metal"/>
      </visual>

      <collision>
        <origin xyz="0 0 0" rpy="0 0 0" />
        <geometry>
          <mesh filename="package://puma560_description/meshes/puma_link_1_collision.stl" />
        </geometry>
      </collision>

      <!-- Inertia parameters 
      mass and center of mass (com)
      inertia_diagonal defined as [Ixx Iyy Izz]
      inertia_off_diagonal defined as [Ixy Ixz Iyz]
    

    <xacro:general_inertia_definition
      mass="4.43413" 
      com="${[-0.000000, 0.022503, -0.002794, 0, 0, 0]}"
      inertia_diagonal="${[0.02733, 0.01332, 0.02716]}"
      inertia_off_diagonal="${[0, 0, -0.00028 ]}"
      />

      <!-- Inertia parameters 
      mass and center of mass (com)
      inertia_diagonal defined as [Ixx Iyy Izz]
      inertia_off_diagonal defined as [Ixy Ixz Iyz]
    -->

    <xacro:general_inertia_definition
      mass="11.97216" 
      com="${[-0.000000, 0.022503, -0.002794, 0, 0, 0]}"
      inertia_diagonal="${[0.07379, 0.03595, 0.07334]}"
      inertia_off_diagonal="${[0, 0, -0.00075]}"
      />

    </link>

    <joint name="link_2" type="continuous">
      <parent link="puma_link_1"/>
      <child link="puma_link_2"/>
      <origin xyz="0 ${offset_y_link_2} 0" rpy="${Pi/2} 0 0" />
      <axis xyz="0 0 1" />
    </joint>

    <link name="puma_link_2">

      <visual>
        <origin xyz="0 0 0" rpy="0 0 0" />
        <geometry>
          <mesh filename="package://puma560_description/meshes/puma_link_2.stl" />
        </geometry>
        <material name="metal"/>
      </visual>

      <collision>
        <origin xyz="0 0 0" rpy="0 0 0" />
        <geometry>
          <mesh filename="package://puma560_description/meshes/puma_link_2_collision.stl" />
        </geometry>
      </collision>

      <!-- Inertia parameters 
      mass and center of mass (com)
      inertia_diagonal defined as [Ixx Iyy Izz]
      inertia_off_diagonal defined as [Ixy Ixz Iyz]
    

    <xacro:general_inertia_definition
      mass="4.43413" 
      com="${[-0.000000, 0.022503, -0.002794, 0, 0, 0]}"
      inertia_diagonal="${[0.02733, 0.01332, 0.02716]}"
      inertia_off_diagonal="${[0, 0, -0.00028 ]}"
      />

      <!-- Inertia parameters 
      mass and center of mass (com)
      inertia_diagonal defined as [Ixx Iyy Izz]
      inertia_off_diagonal defined as [Ixy Ixz Iyz]
    -->

    <xacro:general_inertia_definition
      mass="11.97216" 
      com="${[-0.000000, 0.022503, -0.002794, 0, 0, 0]}"
      inertia_diagonal="${[0.07379, 0.03595, 0.07334]}"
      inertia_off_diagonal="${[0, 0, -0.00075]}"
      />

    </link>

  </robot>
